Workbook
Name \I: #REF!
Name _1: #REF!
Name AAA: #REF!
Name AAAFD: #REF!
Name ADITIVO_PLANEJAMENTO: #REF!
Name ADITIVO_PLANEJAMENTO: #REF!
Name Atividades: #REF!
Name Atividades: #REF!
Name Atividades: #REF!
Name Atividades: #REF!
Name Atividades: #REF!
Name DEGRAU: #REF!
Name ESTRUTURA: #REF!
Name ESTRUTURA: #REF!
Name ESTRUTURA: #REF!
Name ESTRUTURA: #REF!
Name Fornecedores: INDIRECT("'Fornecedores'!B2:B"&COUNTA(#REF!)+2)
Name Fornecedores: INDIRECT("'Fornecedores'!B2:B"&COUNTA(#REF!)+2)
Name Fornecedores: INDIRECT("'Fornecedores'!B2:B"&COUNTA(#REF!)+2)
Name Fornecedores: INDIRECT("'Fornecedores'!B2:B"&COUNTA(#REF!)+2)
Name FORPINT: #REF!
Name FORRO: #REF!
Name MACRO: #REF!
Name MATERIAL: #REF!
Name MOBRA: #REF!
Name motivo_aditivo: #REF!
Name motivo_aditivo: #REF!
Name motivo_aditivo: #REF!
Name motivo_quantidade: #REF!
Name motivo_quantidade: #REF!
Name motivo_quantidade: #REF!
Name motivo_quantidade: #REF!
Name Motivo_unitário: #REF!
Name Motivo_unitário: #REF!
Name Motivo_unitário: #REF!
Name Motivo_unitário: #REF!
Name Motivosdoaditivo: #REF!
Name Motivosdoaditivo: #REF!
Name Motivosdoaditivo: #REF!
Name Motivosdoaditivo: #REF!
Name Obras: INDIRECT("'02 - Tipologia'!C4:C"&10-COUNTIF(#REF!,"")+3)
Name ok: #REF!
Name PINTURA: #REF!
Name PINTURA: #REF!
Name PINTURA: #REF!
Name PISO: #REF!
Name quantidade_oi: '2. Boletim de Medição'!#REF!
Name quantidade_oi: '3. Faturamento Direto'!#REF!
Name quantidade_oi: tbFaturamento!#REF!
Name quantidade_pre: '2. Boletim de Medição'!#REF!
Name quantidade_pre: '3. Faturamento Direto'!#REF!
Name quantidade_pre: tbFaturamento!#REF!
Name quantidade_sup: #REF!
Name quantidade_sup: #REF!
Name quantidade_sup: #REF!
Name quantidade_sup: #REF!
Name quantidade_sup: #REF!
Name Responsável_quantidade: #REF!
Name Responsável_quantidade: #REF!
Name Responsável_quantidade: #REF!

Sheet PIVOT
A1: EVOLUÇÃO FÍSICA X FINANCEIRA | E1: DISTRIBUIÇÃO FINANCEIRA | H1: STATUS DOS PAVIMENTOS | K1: PRODUTIVIDADE m² | O1: PENDÊNCIA POR SERVIÇO | S1: PREVISTO
A2: Rótulos de Linha | B2: % Financeiro | E2: Rótulos de Linha | F2: Soma de VALOR | H2: Rótulos de Linha | I2: Soma de % | K2: Rótulos de Linha | L2: EXECUTADO | M2: ACUMULADO | O2: Rótulos de Linha | P2: Soma de PENDENTE | S2: Rótulos de Linha | T2: Soma de PREVISTO ACUM. | U2: Soma de REALIZADO ACUM.
A3: 46014 | B3: 0.044680905 | E3: Executado | F3: 270307 | H3: B2 | I3: 0.014463161 | K3: 45951 | L3: 2195.2 | M3: 2195.2 | O3: Colocacao de Azulejo | P3: 235.36 | S3: 1 | T3: 11754 | U3: 2136
A4: 45951 | B4: 0.09910082 | E4: Retenção | F4: 18921.49 | H4: B5 | I4: 0.039135613 | K4: 45985 | L4: 3271.05 | M4: 5466.25 | O4: Colocação de soleiras | P4: 337 | S4: 2 | T4: 23508 | U4: 3541
A5: 46139 | B5: 0.11182586 | E5: Saldo | F5: 0 | H5: B6 | I5: 0.047643355 | K5: 46014 | L5: 1315.93 | M5: 6782.18 | O5: Colocação de baguetes | P5: 353 | S5: 3 | T5: 35262 | U5: 4337
A6: 45985 | B6: 0.24315783 | E6: Total Geral | F6: 289228.49 | H6: B3 | I6: 0.072315807 | K6: 46134 | L6: 829.79 | M6: 7611.97 | O6: Colocacao Piso Ceramico | P6: 2393.32 | S6: 4 | T6: 47016 | U6: 5166.79
A7: 46134 | B7: 0.2605431 | H7: B0 | I7: 0.077420453 | K7: 46139 | L7: 265.2 | M7: 7877.17 | O7: Rodapé Cerâmico | Porcelanato | P7: 5942.8 | S7: 5 | T7: 58770 | U7: 5222.79
A8: Total Geral | B8: 0.75930852 | H8: B1 | I8: 0.088480517 | K8: Total Geral | L8: 7877.17 | O8: Total Geral | P8: 9261.48 | S8: 6 | T8: 70524 | U8: 5222.79
H9: B4 | I9: 0.13952697 | S9: 7 | T9: 82278 | U9: 5222.79
H10: B8 | I10: 0.14378084 | K10: Rótulos de Linha | L10: Contagem de EXECUTADO | S10: 8 | T10: 94032 | U10: 5222.79
H11: B7 | I11: 0.15228858 | L11: 10 | S11: 9 | T11: 105786 | U11: 5222.79
H12: B9 | I12: 0.21643696 | K12: 21/10/2025 | L12: 10 | S12: 10 | T12: 117540 | U12: 5222.79
H13: Total Geral | I13: 0.99149226 | K13: 22/04/2026 | L13: 10 | S13: Total Geral | T13: 646470 | U13: 46517.53
K14: 23/12/2025 | L14: 10
K15: 24/11/2025 | L15: 10
K16: 27/04/2026 | L16: 10
K17: Total Geral | L17: 10

Sheet tbPrevisto
A1: MEDIÇÕES | B1: DATA | C1: PREVISTO | D1: REALIZADO | E1: PREVISTO ACUM. | F1: REALIZADO ACUM.
A2: 1 | B2: =Tabela57[[#This Row],[DATA]] -> 45951 | C2: 11754 | D2: =Tabela573[[#This Row],[EXECUTADO]] -> 2136 | E2: =Tabela51112[[#This Row],[PREVISTO]] -> 11754 | F2: =SUM(F1,Tabela573[[#This Row],[EXECUTADO]]) -> 2136
A3: 2 | B3: =Tabela57[[#This Row],[DATA]] -> 45985 | C3: 11754 | D3: =Tabela573[[#This Row],[EXECUTADO]] -> 1405 | E3: =Tabela51112[[#This Row],[PREVISTO]]+C2 -> 23508 | F3: =SUM(D2:D3) -> 3541
A4: 3 | B4: =Tabela57[[#This Row],[DATA]] -> 46014 | C4: 11754 | D4: =Tabela573[[#This Row],[EXECUTADO]] -> 796 | E4: =Tabela51112[[#This Row],[PREVISTO]]+C2+C3 -> 35262 | F4: =SUM(D2:D4) -> 4337
A5: 4 | B5: =Tabela57[[#This Row],[DATA]] -> 46134 | C5: 11754 | D5: =Tabela573[[#This Row],[EXECUTADO]] -> 829.79 | E5: =Tabela51112[[#This Row],[PREVISTO]]+C4+C3+C2 -> 47016 | F5: =SUM(D2:D5) -> 5166.79
A6: 5 | B6: =Tabela57[[#This Row],[DATA]] -> 46139 | C6: 11754 | D6: =Tabela573[[#This Row],[EXECUTADO]] -> 56 | E6: =Tabela51112[[#This Row],[PREVISTO]]+C5+C4+C3+C2 -> 58770 | F6: =SUM(D2:D6) -> 5222.79
A7: 6 | C7: 11754 | D7: =Tabela573[[#This Row],[EXECUTADO]] | E7: =SUM(E6,C6) -> 70524 | F7: =SUM(D2:D7) -> 5222.79
A8: 7 | C8: 11754 | D8: =Tabela573[[#This Row],[EXECUTADO]] | E8: =SUM(E7,C7) -> 82278 | F8: =SUM(D2:D8) -> 5222.79
A9: 8 | C9: 11754 | D9: =Tabela573[[#This Row],[EXECUTADO]] | E9: =SUM(E8,C8) -> 94032 | F9: =SUM(D2:D9) -> 5222.79
A10: 9 | C10: 11754 | D10: =Tabela573[[#This Row],[EXECUTADO]] | E10: =SUM(E9,C9) -> 105786 | F10: =SUM(D2:D10) -> 5222.79
A11: 10 | C11: 11754 | D11: =Tabela573[[#This Row],[EXECUTADO]] | E11: =SUM(E10,C10) -> 117540 | F11: =SUM(Tabela51112[REALIZADO]) -> 5222.79

Sheet tbPendencias
A1: CÓD | B1: DESCRIÇÃO | C1: PENDENTE
A2: 1.1.1 | B2: Colocacao de Azulejo | C2: =SUM(tbBoletim!E3)-SUM(Tabela5[[#This Row],[TOTAL F0]:[TOTAL F9]]) -> 235.36
A3: 1.1.2 | B3: Colocacao Piso Ceramico | C3: =SUM(tbBoletim!E4)-SUM(Tabela5[[#This Row],[TOTAL F0]:[TOTAL F9]]) -> 2393.32
A4: 1.1.3 | B4: Colocação de soleiras | C4: =SUM(tbBoletim!E5)-SUM(Tabela5[[#This Row],[TOTAL F0]:[TOTAL F9]]) -> 337
A5: 1.1.4 | B5: Colocação de baguetes | C5: =SUM(tbBoletim!E6)-SUM(Tabela5[[#This Row],[TOTAL F0]:[TOTAL F9]]) -> 353
A6: 1.1.5 | B6: Rodapé Cerâmico | Porcelanato | C6: =SUM(tbBoletim!E7)-SUM(Tabela5[[#This Row],[TOTAL F0]:[TOTAL F9]]) -> 5942.8

Sheet tbCategoria
A1: CATEGORIA | B1: VALOR
A2: Executado | B2: ='1. Controle de Contrato'!G21 -> 270307
A3: Saldo | B3: ='1. Controle de Contrato'!K21 -> 0
A4: Retenção | B4: ='1. Controle de Contrato'!I21 -> 18921.49

Sheet tbMapaData
A1: MEDIÇÃO | B1: DATA | C1: MÊS/ANO
A2: 1 | B2: 45951 | C2: =TEXT(Tabela57[[#This Row],[DATA]],"mmm/aa") -> out/25
A3: 2 | B3: 45985 | C3: =TEXT(Tabela57[[#This Row],[DATA]],"mmm/aa") -> nov/25
A4: 3 | B4: 46014 | C4: =TEXT(Tabela57[[#This Row],[DATA]],"mmm/aa") -> dez/25
A5: 4 | B5: 46134 | C5: =TEXT(Tabela57[[#This Row],[DATA]],"mmm/aa") -> abr/26
A6: 5 | B6: 46139 | C6: =TEXT(Tabela57[[#This Row],[DATA]],"mmm/aa") -> abr/26
A7: 6 | C7: =TEXT(Tabela57[[#This Row],[DATA]],"mmm/aa") -> jan/00
A8: 7 | C8: =TEXT(Tabela57[[#This Row],[DATA]],"mmm/aa") -> jan/00
A9: 8 | C9: =TEXT(Tabela57[[#This Row],[DATA]],"mmm/aa") -> jan/00
A10: 9 | C10: =TEXT(Tabela57[[#This Row],[DATA]],"mmm/aa") -> jan/00
A11: 10 | C11: =TEXT(Tabela57[[#This Row],[DATA]],"mmm/aa") -> jan/00
A12: 11 | C12: =TEXT(Tabela57[[#This Row],[DATA]],"mmm/aa") -> jan/00

Sheet tbMapa
A1: CÓD | B1: DESCRIÇÃO | C1: TORRE | D1: MEDIÇÃO | E1: TOTAL F0 | F1: TOTAL F1 | G1: TOTAL F2 | H1: TOTAL F3 | I1: TOTAL F4 | J1: TOTAL F5 | K1: TOTAL F6 | L1: TOTAL F7 | M1: TOTAL F8 | N1: TOTAL F9
A2: 1.1.1 | B2: Mao de Obra Colocacao de Azulejo | C2: A | D2: M² | E2: =SUM('4. Mapa Visual de Medição'!G10:G21) -> 87.48 | F2: =SUM('4. Mapa Visual de Medição'!H10:H21) -> 87.48 | G2: =SUM('4. Mapa Visual de Medição'!I10:I21) -> 87.48 | H2: =SUM('4. Mapa Visual de Medição'!J10:J21) -> 87.48 | I2: =SUM('4. Mapa Visual de Medição'!K10:K21) -> 58.32 | J2: =SUM('4. Mapa Visual de Medição'!L10:L21) -> 87.48 | K2: =SUM('4. Mapa Visual de Medição'!M10:M21) -> 87.48 | L2: =SUM('4. Mapa Visual de Medição'!N10:N21) -> 87.48 | ... N2: =SUM('4. Mapa Visual de Medição'!P10:P21) -> 87.48
A3: 1.1.2 | B3: Mao de Obra Colocacao Piso Ceramico | C3: A | D3: M² | E3: =SUM('4. Mapa Visual de Medição'!BV10:BV21) -> 84.6 | F3: =SUM('4. Mapa Visual de Medição'!BW10:BW21) -> 60.84 | G3: =SUM('4. Mapa Visual de Medição'!BX10:BX21) -> 40.56 | H3: =SUM('4. Mapa Visual de Medição'!BY10:BY21) -> 40.56 | I3: =SUM('4. Mapa Visual de Medição'!BZ10:BZ21) -> 56.4 | J3: =SUM('4. Mapa Visual de Medição'!CA10:CA21) -> 84.6 | K3: =SUM('4. Mapa Visual de Medição'!CB10:CB21) -> 60.84 | L3: =SUM('4. Mapa Visual de Medição'!CC10:CC21) -> 60.84 | ... N3: =SUM('4. Mapa Visual de Medição'!CE10:CE21) -> 84.6
A4: 1.1.3 | B4: M.O para colocação de soleiras | C4: A | D4: M² | E4: =SUM('4. Mapa Visual de Medição'!EJ10:EJ21) -> 0 | F4: =SUM('4. Mapa Visual de Medição'!EK10:EK21) -> 0 | G4: =SUM('4. Mapa Visual de Medição'!EL10:EL21) -> 0 | H4: =SUM('4. Mapa Visual de Medição'!EM10:EM21) -> 0 | I4: =SUM('4. Mapa Visual de Medição'!EN10:EN21) -> 0 | J4: =SUM('4. Mapa Visual de Medição'!EO10:EO21) -> 0 | K4: =SUM('4. Mapa Visual de Medição'!EP10:EP21) -> 0 | L4: =SUM('4. Mapa Visual de Medição'!EQ10:EQ21) -> 0 | ... N4: =SUM('4. Mapa Visual de Medição'!ES10:ES21) -> 0
A5: 1.1.4 | B5: M.O. para colocação de baguetes | C5: A | D5: M² | E5: =SUM('4. Mapa Visual de Medição'!GW10:GW21) -> 0 | F5: =SUM('4. Mapa Visual de Medição'!GX10:GX21) -> 0 | G5: =SUM('4. Mapa Visual de Medição'!GY10:GY21) -> 0 | H5: =SUM('4. Mapa Visual de Medição'!GZ10:GZ21) -> 0 | I5: =SUM('4. Mapa Visual de Medição'!HA10:HA21) -> 0 | J5: =SUM('4. Mapa Visual de Medição'!HB10:HB21) -> 0 | K5: =SUM('4. Mapa Visual de Medição'!HC10:HC21) -> 0 | L5: =SUM('4. Mapa Visual de Medição'!HD10:HD21) -> 0 | ... N5: =SUM('4. Mapa Visual de Medição'!HF10:HF21) -> 0
A6: 1.1.5 | B6: Rodapé Cerâmico | Porcelanato - Serviço M.O Subcontrato | C6: A | D6: M² | E6: =SUM('4. Mapa Visual de Medição'!JI10:JI21) -> 141.6 | F6: =SUM('4. Mapa Visual de Medição'!JJ10:JJ21) -> 98.4 | G6: =SUM('4. Mapa Visual de Medição'!JK10:JK21) -> 73.8 | H6: =SUM('4. Mapa Visual de Medição'!JL10:JL21) -> 73.8 | I6: =SUM('4. Mapa Visual de Medição'!JM10:JM21) -> 106.2 | J6: =SUM('4. Mapa Visual de Medição'!JN10:JN21) -> 106.2 | K6: =SUM('4. Mapa Visual de Medição'!JO10:JO21) -> 73.8 | L6: =SUM('4. Mapa Visual de Medição'!JP10:JP21) -> 98.4 | ... N6: =SUM('4. Mapa Visual de Medição'!JR10:JR21) -> 141.6

Sheet tbPavimento
A1: PAVIMENTO | B1: EXECUTADO | C1: PREVISTO | D1: %
A2: B0 | B2: 91 | C2: {=SUM(Tabela108[PREVISTO TOTAL]/10)} -> 1175.4 | D2: =Tabela9[[#This Row],[EXECUTADO]]/Tabela9[[#This Row],[PREVISTO]] -> 0.077420453
A3: B1 | B3: 104 | C3: {=SUM(Tabela108[PREVISTO TOTAL]/10)} -> 1175.4 | D3: =Tabela9[[#This Row],[EXECUTADO]]/Tabela9[[#This Row],[PREVISTO]] -> 0.088480517
A4: B2 | B4: 17 | C4: {=SUM(Tabela108[PREVISTO TOTAL]/10)} -> 1175.4 | D4: =Tabela9[[#This Row],[EXECUTADO]]/Tabela9[[#This Row],[PREVISTO]] -> 0.014463161
A5: B3 | B5: 85 | C5: {=SUM(Tabela108[PREVISTO TOTAL]/10)} -> 1175.4 | D5: =Tabela9[[#This Row],[EXECUTADO]]/Tabela9[[#This Row],[PREVISTO]] -> 0.072315807
A6: B4 | B6: 164 | C6: {=SUM(Tabela108[PREVISTO TOTAL]/10)} -> 1175.4 | D6: =Tabela9[[#This Row],[EXECUTADO]]/Tabela9[[#This Row],[PREVISTO]] -> 0.13952697
A7: B5 | B7: 46 | C7: {=SUM(Tabela108[PREVISTO TOTAL]/10)} -> 1175.4 | D7: =Tabela9[[#This Row],[EXECUTADO]]/Tabela9[[#This Row],[PREVISTO]] -> 0.039135613
A8: B6 | B8: 56 | C8: {=SUM(Tabela108[PREVISTO TOTAL]/10)} -> 1175.4 | D8: =Tabela9[[#This Row],[EXECUTADO]]/Tabela9[[#This Row],[PREVISTO]] -> 0.047643355
A9: B7 | B9: 179 | C9: {=SUM(Tabela108[PREVISTO TOTAL]/10)} -> 1175.4 | D9: =Tabela9[[#This Row],[EXECUTADO]]/Tabela9[[#This Row],[PREVISTO]] -> 0.15228858
A10: B8 | B10: 169 | C10: 1175.4 | D10: =Tabela9[[#This Row],[EXECUTADO]]/Tabela9[[#This Row],[PREVISTO]] -> 0.14378084
A11: B9 | B11: 254.4 | C11: {=SUM(Tabela108[PREVISTO TOTAL]/10)} -> 1175.4 | D11: =Tabela9[[#This Row],[EXECUTADO]]/Tabela9[[#This Row],[PREVISTO]] -> 0.21643696

Sheet tbContrato
A1: Nº Medição | B1: Período | C1: Data | D1: Nº NF | E1: Valor Medição | F1: Dedução Medição | G1: Retenção Medição | H1: Valor Medição Líquido | I1: Saldo Medição | J1: Faturamento Direto | K1: Saldo Faturamento Direto | L1: Total Pago | M1: Saldo Contratual | N1: Status
A2: ='1. Controle de Contrato'!C24 -> 1 | B2: ='1. Controle de Contrato'!D24 -> 45931 | C2: ='1. Controle de Contrato'!E24 -> 45951 | D2: ='1. Controle de Contrato'!F24 -> 0 | E2: ='1. Controle de Contrato'!G24 -> 35279 | F2: ='1. Controle de Contrato'!H24 -> 0 | G2: ='1. Controle de Contrato'!I24 -> 2469.53 | H2: ='1. Controle de Contrato'!J24 -> 32809.47 | ... N2: ='1. Controle de Contrato'!P24 -> 0.86948544
A3: ='1. Controle de Contrato'!C25 -> 2 | B3: ='1. Controle de Contrato'!D25 -> 45962 | C3: ='1. Controle de Contrato'!E25 -> 45985 | D3: ='1. Controle de Contrato'!F25 -> 0 | E3: ='1. Controle de Contrato'!G25 -> 86562 | F3: ='1. Controle de Contrato'!H25 -> 0 | G3: ='1. Controle de Contrato'!I25 -> 6059.34 | H3: ='1. Controle de Contrato'!J25 -> 80502.66 | ... N3: ='1. Controle de Contrato'!P25 -> 0.54924956
A4: ='1. Controle de Contrato'!C26 -> 3 | B4: ='1. Controle de Contrato'!D26 -> 45992 | C4: ='1. Controle de Contrato'!E26 -> 46014 | D4: ='1. Controle de Contrato'!F26 -> 0 | E4: ='1. Controle de Contrato'!G26 -> 15906 | F4: ='1. Controle de Contrato'!H26 -> 0 | G4: ='1. Controle de Contrato'!I26 -> 1113.42 | H4: ='1. Controle de Contrato'!J26 -> 14792.58 | ... N4: ='1. Controle de Contrato'!P26 -> 0.49040535
A5: ='1. Controle de Contrato'!C27 -> 4 | B5: ='1. Controle de Contrato'!D27 -> 46113 | C5: ='1. Controle de Contrato'!E27 -> 46134 | D5: ='1. Controle de Contrato'!F27 -> 0 | E5: ='1. Controle de Contrato'!G27 -> 92751 | F5: ='1. Controle de Contrato'!H27 -> 0 | G5: ='1. Controle de Contrato'!I27 -> 6492.57 | H5: ='1. Controle de Contrato'!J27 -> 86258.43 | ... N5: ='1. Controle de Contrato'!P27 -> 0.14727329
A6: ='1. Controle de Contrato'!C28 -> 5 | B6: ='1. Controle de Contrato'!D28 -> 46113 | C6: ='1. Controle de Contrato'!E28 -> 46139 | D6: ='1. Controle de Contrato'!F28 -> 0 | E6: ='1. Controle de Contrato'!G28 -> 39809 | F6: ='1. Controle de Contrato'!H28 -> 0 | G6: ='1. Controle de Contrato'!I28 -> 2786.63 | H6: ='1. Controle de Contrato'!J28 -> 37022.37 | ... N6: ='1. Controle de Contrato'!P28
A7: ='1. Controle de Contrato'!C29 -> 6 | B7: ='1. Controle de Contrato'!D29 | C7: ='1. Controle de Contrato'!E29 | D7: ='1. Controle de Contrato'!F29 -> 0 | E7: ='1. Controle de Contrato'!G29 -> 0 | F7: ='1. Controle de Contrato'!H29 -> 0 | G7: ='1. Controle de Contrato'!I29 -> 0 | H7: ='1. Controle de Contrato'!J29 -> 0 | ... N7: ='1. Controle de Contrato'!P29
A8: ='1. Controle de Contrato'!C30 -> 7 | B8: ='1. Controle de Contrato'!D30 | C8: ='1. Controle de Contrato'!E30 | D8: ='1. Controle de Contrato'!F30 -> 0 | E8: ='1. Controle de Contrato'!G30 -> 0 | F8: ='1. Controle de Contrato'!H30 -> 0 | G8: ='1. Controle de Contrato'!I30 -> 0 | H8: ='1. Controle de Contrato'!J30 -> 0 | ... N8: ='1. Controle de Contrato'!P30
A9: ='1. Controle de Contrato'!C31 -> 8 | B9: ='1. Controle de Contrato'!D31 | C9: ='1. Controle de Contrato'!E31 | D9: ='1. Controle de Contrato'!F31 -> 0 | E9: ='1. Controle de Contrato'!G31 -> 0 | F9: ='1. Controle de Contrato'!H31 -> 0 | G9: ='1. Controle de Contrato'!I31 -> 0 | H9: ='1. Controle de Contrato'!J31 -> 0 | ... N9: ='1. Controle de Contrato'!P31
A10: ='1. Controle de Contrato'!C32 -> 9 | B10: ='1. Controle de Contrato'!D32 | C10: ='1. Controle de Contrato'!E32 | D10: ='1. Controle de Contrato'!F32 -> 0 | E10: ='1. Controle de Contrato'!G32 -> 0 | F10: ='1. Controle de Contrato'!H32 -> 0 | G10: ='1. Controle de Contrato'!I32 -> 0 | H10: ='1. Controle de Contrato'!J32 -> 0 | ... N10: ='1. Controle de Contrato'!P32
A11: ='1. Controle de Contrato'!C33 -> 10 | B11: ='1. Controle de Contrato'!D33 | C11: ='1. Controle de Contrato'!E33 | D11: ='1. Controle de Contrato'!F33 -> 0 | E11: ='1. Controle de Contrato'!G33 -> 0 | F11: ='1. Controle de Contrato'!H33 -> 0 | G11: ='1. Controle de Contrato'!I33 -> 0 | H11: ='1. Controle de Contrato'!J33 -> 0 | ... N11: ='1. Controle de Contrato'!P33
A12: ='1. Controle de Contrato'!C34 -> 11 | B12: ='1. Controle de Contrato'!D34 | C12: ='1. Controle de Contrato'!E34 | D12: ='1. Controle de Contrato'!F34 -> 0 | E12: ='1. Controle de Contrato'!G34 -> 0 | F12: ='1. Controle de Contrato'!H34 -> 0 | G12: ='1. Controle de Contrato'!I34 -> 0 | H12: ='1. Controle de Contrato'!J34 -> 0 | ... N12: ='1. Controle de Contrato'!P34
A13: ='1. Controle de Contrato'!C35 -> 12 | B13: ='1. Controle de Contrato'!D35 | C13: ='1. Controle de Contrato'!E35 | D13: ='1. Controle de Contrato'!F35 -> 0 | E13: ='1. Controle de Contrato'!G35 -> 0 | F13: ='1. Controle de Contrato'!H35 -> 0 | G13: ='1. Controle de Contrato'!I35 -> 0 | H13: ='1. Controle de Contrato'!J35 -> 0 | ... N13: ='1. Controle de Contrato'!P35
... A21: ='1. Controle de Contrato'!C43 -> 20 | B21: ='1. Controle de Contrato'!D43 | C21: ='1. Controle de Contrato'!E43 | D21: ='1. Controle de Contrato'!F43 -> 0 | E21: ='1. Controle de Contrato'!G43 -> 0 | F21: ='1. Controle de Contrato'!H43 -> 0 | G21: ='1. Controle de Contrato'!I43 -> 0 | H21: ='1. Controle de Contrato'!J43 -> 0 | ... N21: ='1. Controle de Contrato'!P43
A22: =A21+1 -> 21 | B22: =IF(IFERROR(_xlfn.XLOOKUP(A22,'2. Boletim de Medição'!$10:$10,'2. Boletim de Medição'!$6:$6),"")>0,IFERROR(_xlfn.XLOOKUP(A22,'2. Boletim de Medição'!$10:$10,'2. Boletim de Medição'!$6:$6),""),"") | C22: =IF(IFERROR(_xlfn.XLOOKUP(A22,'2. Boletim de Medição'!$10:$10,'2. Boletim de Medição'!$7:$7),"")>0,IFERROR(_xlfn.XLOOKUP(A22,'2. Boletim de Medição'!$10:$10,'2. Boletim de Medição'!$7:$7),""),"") | E22: =IFERROR(_xlfn.XLOOKUP(A22,'2. Boletim de Medição'!$10:$10,'2. Boletim de Medição'!$13:$13),0) -> 0 | F22: =IFERROR(_xlfn.XLOOKUP(A22,'2. Boletim de Medição'!$10:$10,'2. Boletim de Medição'!$34:$34),0) -> 0 | G22: =IFERROR(E22*#REF!,0) -> 0 | H22: =IFERROR(E22-F22-G22,0) -> 0 | I22: =IF(E22>0,I21-E22,0) -> 0 | J22: =IFERROR(_xlfn.XLOOKUP(A22,'3. Faturamento Direto'!$9:$9,'3. Faturamento Direto'!$13:$13),0) -> 0 | K22: =IF(J22>0,K21-J22,0) -> 0 | L22: =E22+J22 -> 0 | M22: =IF(L22>0,M21-L22,0) -> 0 | N22: =IF(M22>0,M22/#REF!,"")
A23: =A22+1 -> 22 | B23: =IF(IFERROR(_xlfn.XLOOKUP(A23,'2. Boletim de Medição'!$10:$10,'2. Boletim de Medição'!$6:$6),"")>0,IFERROR(_xlfn.XLOOKUP(A23,'2. Boletim de Medição'!$10:$10,'2. Boletim de Medição'!$6:$6),""),"") | C23: =IF(IFERROR(_xlfn.XLOOKUP(A23,'2. Boletim de Medição'!$10:$10,'2. Boletim de Medição'!$7:$7),"")>0,IFERROR(_xlfn.XLOOKUP(A23,'2. Boletim de Medição'!$10:$10,'2. Boletim de Medição'!$7:$7),""),"") | E23: =IFERROR(_xlfn.XLOOKUP(A23,'2. Boletim de Medição'!$10:$10,'2. Boletim de Medição'!$13:$13),0) -> 0 | F23: =IFERROR(_xlfn.XLOOKUP(A23,'2. Boletim de Medição'!$10:$10,'2. Boletim de Medição'!$34:$34),0) -> 0 | G23: =IFERROR(E23*#REF!,0) -> 0 | H23: =IFERROR(E23-F23-G23,0) -> 0 | I23: =IF(E23>0,I22-E23,0) -> 0 | J23: =IFERROR(_xlfn.XLOOKUP(A23,'3. Faturamento Direto'!$9:$9,'3. Faturamento Direto'!$13:$13),0) -> 0 | K23: =IF(J23>0,K22-J23,0) -> 0 | L23: =E23+J23 -> 0 | M23: =IF(L23>0,M22-L23,0) -> 0 | N23: =IF(M23>0,M23/#REF!,"")
A24: =A23+1 -> 23 | B24: =IF(IFERROR(_xlfn.XLOOKUP(A24,'2. Boletim de Medição'!$10:$10,'2. Boletim de Medição'!$6:$6),"")>0,IFERROR(_xlfn.XLOOKUP(A24,'2. Boletim de Medição'!$10:$10,'2. Boletim de Medição'!$6:$6),""),"") | C24: =IF(IFERROR(_xlfn.XLOOKUP(A24,'2. Boletim de Medição'!$10:$10,'2. Boletim de Medição'!$7:$7),"")>0,IFERROR(_xlfn.XLOOKUP(A24,'2. Boletim de Medição'!$10:$10,'2. Boletim de Medição'!$7:$7),""),"") | E24: =IFERROR(_xlfn.XLOOKUP(A24,'2. Boletim de Medição'!$10:$10,'2. Boletim de Medição'!$13:$13),0) -> 0 | F24: =IFERROR(_xlfn.XLOOKUP(A24,'2. Boletim de Medição'!$10:$10,'2. Boletim de Medição'!$34:$34),0) -> 0 | G24: =IFERROR(E24*#REF!,0) -> 0 | H24: =IFERROR(E24-F24-G24,0) -> 0 | I24: =IF(E24>0,I23-E24,0) -> 0 | J24: =IFERROR(_xlfn.XLOOKUP(A24,'3. Faturamento Direto'!$9:$9,'3. Faturamento Direto'!$13:$13),0) -> 0 | K24: =IF(J24>0,K23-J24,0) -> 0 | L24: =E24+J24 -> 0 | M24: =IF(L24>0,M23-L24,0) -> 0 | N24: =IF(M24>0,M24/#REF!,"")
A25: =A24+1 -> 24 | B25: =IF(IFERROR(_xlfn.XLOOKUP(A25,'2. Boletim de Medição'!$10:$10,'2. Boletim de Medição'!$6:$6),"")>0,IFERROR(_xlfn.XLOOKUP(A25,'2. Boletim de Medição'!$10:$10,'2. Boletim de Medição'!$6:$6),""),"") | C25: =IF(IFERROR(_xlfn.XLOOKUP(A25,'2. Boletim de Medição'!$10:$10,'2. Boletim de Medição'!$7:$7),"")>0,IFERROR(_xlfn.XLOOKUP(A25,'2. Boletim de Medição'!$10:$10,'2. Boletim de Medição'!$7:$7),""),"") | E25: =IFERROR(_xlfn.XLOOKUP(A25,'2. Boletim de Medição'!$10:$10,'2. Boletim de Medição'!$13:$13),0) -> 0 | F25: =IFERROR(_xlfn.XLOOKUP(A25,'2. Boletim de Medição'!$10:$10,'2. Boletim de Medição'!$34:$34),0) -> 0 | G25: =IFERROR(E25*#REF!,0) -> 0 | H25: =IFERROR(E25-F25-G25,0) -> 0 | I25: =IF(E25>0,I24-E25,0) -> 0 | J25: =IFERROR(_xlfn.XLOOKUP(A25,'3. Faturamento Direto'!$9:$9,'3. Faturamento Direto'!$13:$13),0) -> 0 | K25: =IF(J25>0,K24-J25,0) -> 0 | L25: =E25+J25 -> 0 | M25: =IF(L25>0,M24-L25,0) -> 0 | N25: =IF(M25>0,M25/#REF!,"")
A26: =A25+1 -> 25 | B26: =IF(IFERROR(_xlfn.XLOOKUP(A26,'2. Boletim de Medição'!$10:$10,'2. Boletim de Medição'!$6:$6),"")>0,IFERROR(_xlfn.XLOOKUP(A26,'2. Boletim de Medição'!$10:$10,'2. Boletim de Medição'!$6:$6),""),"") | C26: =IF(IFERROR(_xlfn.XLOOKUP(A26,'2. Boletim de Medição'!$10:$10,'2. Boletim de Medição'!$7:$7),"")>0,IFERROR(_xlfn.XLOOKUP(A26,'2. Boletim de Medição'!$10:$10,'2. Boletim de Medição'!$7:$7),""),"") | E26: =IFERROR(_xlfn.XLOOKUP(A26,'2. Boletim de Medição'!$10:$10,'2. Boletim de Medição'!$13:$13),0) -> 0 | F26: =IFERROR(_xlfn.XLOOKUP(A26,'2. Boletim de Medição'!$10:$10,'2. Boletim de Medição'!$34:$34),0) -> 0 | G26: =IFERROR(E26*#REF!,0) -> 0 | H26: =IFERROR(E26-F26-G26,0) -> 0 | I26: =IF(E26>0,I25-E26,0) -> 0 | J26: =IFERROR(_xlfn.XLOOKUP(A26,'3. Faturamento Direto'!$9:$9,'3. Faturamento Direto'!$13:$13),0) -> 0 | K26: =IF(J26>0,K25-J26,0) -> 0 | L26: =E26+J26 -> 0 | M26: =IF(L26>0,M25-L26,0) -> 0 | N26: =IF(M26>0,M26/#REF!,"")
A27: =A26+1 -> 26 | B27: =IF(IFERROR(_xlfn.XLOOKUP(A27,'2. Boletim de Medição'!$10:$10,'2. Boletim de Medição'!$6:$6),"")>0,IFERROR(_xlfn.XLOOKUP(A27,'2. Boletim de Medição'!$10:$10,'2. Boletim de Medição'!$6:$6),""),"") | C27: =IF(IFERROR(_xlfn.XLOOKUP(A27,'2. Boletim de Medição'!$10:$10,'2. Boletim de Medição'!$7:$7),"")>0,IFERROR(_xlfn.XLOOKUP(A27,'2. Boletim de Medição'!$10:$10,'2. Boletim de Medição'!$7:$7),""),"") | E27: =IFERROR(_xlfn.XLOOKUP(A27,'2. Boletim de Medição'!$10:$10,'2. Boletim de Medição'!$13:$13),0) -> 0 | F27: =IFERROR(_xlfn.XLOOKUP(A27,'2. Boletim de Medição'!$10:$10,'2. Boletim de Medição'!$34:$34),0) -> 0 | G27: =IFERROR(E27*#REF!,0) -> 0 | H27: =IFERROR(E27-F27-G27,0) -> 0 | I27: =IF(E27>0,I26-E27,0) -> 0 | J27: =IFERROR(_xlfn.XLOOKUP(A27,'3. Faturamento Direto'!$9:$9,'3. Faturamento Direto'!$13:$13),0) -> 0 | K27: =IF(J27>0,K26-J27,0) -> 0 | L27: =E27+J27 -> 0 | M27: =IF(L27>0,M26-L27,0) -> 0 | N27: =IF(M27>0,M27/#REF!,"")
A28: =A27+1 -> 27 | B28: =IF(IFERROR(_xlfn.XLOOKUP(A28,'2. Boletim de Medição'!$10:$10,'2. Boletim de Medição'!$6:$6),"")>0,IFERROR(_xlfn.XLOOKUP(A28,'2. Boletim de Medição'!$10:$10,'2. Boletim de Medição'!$6:$6),""),"") | C28: =IF(IFERROR(_xlfn.XLOOKUP(A28,'2. Boletim de Medição'!$10:$10,'2. Boletim de Medição'!$7:$7),"")>0,IFERROR(_xlfn.XLOOKUP(A28,'2. Boletim de Medição'!$10:$10,'2. Boletim de Medição'!$7:$7),""),"") | E28: =IFERROR(_xlfn.XLOOKUP(A28,'2. Boletim de Medição'!$10:$10,'2. Boletim de Medição'!$13:$13),0) -> 0 | F28: =IFERROR(_xlfn.XLOOKUP(A28,'2. Boletim de Medição'!$10:$10,'2. Boletim de Medição'!$34:$34),0) -> 0 | G28: =IFERROR(E28*#REF!,0) -> 0 | H28: =IFERROR(E28-F28-G28,0) -> 0 | I28: =IF(E28>0,I27-E28,0) -> 0 | J28: =IFERROR(_xlfn.XLOOKUP(A28,'3. Faturamento Direto'!$9:$9,'3. Faturamento Direto'!$13:$13),0) -> 0 | K28: =IF(J28>0,K27-J28,0) -> 0 | L28: =E28+J28 -> 0 | M28: =IF(L28>0,M27-L28,0) -> 0 | N28: =IF(M28>0,M28/#REF!,"")
A29: =A28+1 -> 28 | B29: =IF(IFERROR(_xlfn.XLOOKUP(A29,'2. Boletim de Medição'!$10:$10,'2. Boletim de Medição'!$6:$6),"")>0,IFERROR(_xlfn.XLOOKUP(A29,'2. Boletim de Medição'!$10:$10,'2. Boletim de Medição'!$6:$6),""),"") | C29: =IF(IFERROR(_xlfn.XLOOKUP(A29,'2. Boletim de Medição'!$10:$10,'2. Boletim de Medição'!$7:$7),"")>0,IFERROR(_xlfn.XLOOKUP(A29,'2. Boletim de Medição'!$10:$10,'2. Boletim de Medição'!$7:$7),""),"") | E29: =IFERROR(_xlfn.XLOOKUP(A29,'2. Boletim de Medição'!$10:$10,'2. Boletim de Medição'!$13:$13),0) -> 0 | F29: =IFERROR(_xlfn.XLOOKUP(A29,'2. Boletim de Medição'!$10:$10,'2. Boletim de Medição'!$34:$34),0) -> 0 | G29: =IFERROR(E29*#REF!,0) -> 0 | H29: =IFERROR(E29-F29-G29,0) -> 0 | I29: =IF(E29>0,I28-E29,0) -> 0 | J29: =IFERROR(_xlfn.XLOOKUP(A29,'3. Faturamento Direto'!$9:$9,'3. Faturamento Direto'!$13:$13),0) -> 0 | K29: =IF(J29>0,K28-J29,0) -> 0 | L29: =E29+J29 -> 0 | M29: =IF(L29>0,M28-L29,0) -> 0 | N29: =IF(M29>0,M29/#REF!,"")
A30: =A29+1 -> 29 | B30: =IF(IFERROR(_xlfn.XLOOKUP(A30,'2. Boletim de Medição'!$10:$10,'2. Boletim de Medição'!$6:$6),"")>0,IFERROR(_xlfn.XLOOKUP(A30,'2. Boletim de Medição'!$10:$10,'2. Boletim de Medição'!$6:$6),""),"") | C30: =IF(IFERROR(_xlfn.XLOOKUP(A30,'2. Boletim de Medição'!$10:$10,'2. Boletim de Medição'!$7:$7),"")>0,IFERROR(_xlfn.XLOOKUP(A30,'2. Boletim de Medição'!$10:$10,'2. Boletim de Medição'!$7:$7),""),"") | E30: =IFERROR(_xlfn.XLOOKUP(A30,'2. Boletim de Medição'!$10:$10,'2. Boletim de Medição'!$13:$13),0) -> 0 | F30: =IFERROR(_xlfn.XLOOKUP(A30,'2. Boletim de Medição'!$10:$10,'2. Boletim de Medição'!$34:$34),0) -> 0 | G30: =IFERROR(E30*#REF!,0) -> 0 | H30: =IFERROR(E30-F30-G30,0) -> 0 | I30: =IF(E30>0,I29-E30,0) -> 0 | J30: =IFERROR(_xlfn.XLOOKUP(A30,'3. Faturamento Direto'!$9:$9,'3. Faturamento Direto'!$13:$13),0) -> 0 | K30: =IF(J30>0,K29-J30,0) -> 0 | L30: =E30+J30 -> 0 | M30: =IF(L30>0,M29-L30,0) -> 0 | N30: =IF(M30>0,M30/#REF!,"")
A31: =A30+1 -> 30 | B31: =IF(IFERROR(_xlfn.XLOOKUP(A31,'2. Boletim de Medição'!$10:$10,'2. Boletim de Medição'!$6:$6),"")>0,IFERROR(_xlfn.XLOOKUP(A31,'2. Boletim de Medição'!$10:$10,'2. Boletim de Medição'!$6:$6),""),"") | C31: =IF(IFERROR(_xlfn.XLOOKUP(A31,'2. Boletim de Medição'!$10:$10,'2. Boletim de Medição'!$7:$7),"")>0,IFERROR(_xlfn.XLOOKUP(A31,'2. Boletim de Medição'!$10:$10,'2. Boletim de Medição'!$7:$7),""),"") | E31: =IFERROR(_xlfn.XLOOKUP(A31,'2. Boletim de Medição'!$10:$10,'2. Boletim de Medição'!$13:$13),0) -> 0 | F31: =IFERROR(_xlfn.XLOOKUP(A31,'2. Boletim de Medição'!$10:$10,'2. Boletim de Medição'!$34:$34),0) -> 0 | G31: =IFERROR(E31*#REF!,0) -> 0 | H31: =IFERROR(E31-F31-G31,0) -> 0 | I31: =IF(E31>0,I30-E31,0) -> 0 | J31: =IFERROR(_xlfn.XLOOKUP(A31,'3. Faturamento Direto'!$9:$9,'3. Faturamento Direto'!$13:$13),0) -> 0 | K31: =IF(J31>0,K30-J31,0) -> 0 | L31: =E31+J31 -> 0 | M31: =IF(L31>0,M30-L31,0) -> 0 | N31: =IF(M31>0,M31/#REF!,"")
A32: =A31+1 -> 31 | B32: =IF(IFERROR(_xlfn.XLOOKUP(A32,'2. Boletim de Medição'!$10:$10,'2. Boletim de Medição'!$6:$6),"")>0,IFERROR(_xlfn.XLOOKUP(A32,'2. Boletim de Medição'!$10:$10,'2. Boletim de Medição'!$6:$6),""),"") | C32: =IF(IFERROR(_xlfn.XLOOKUP(A32,'2. Boletim de Medição'!$10:$10,'2. Boletim de Medição'!$7:$7),"")>0,IFERROR(_xlfn.XLOOKUP(A32,'2. Boletim de Medição'!$10:$10,'2. Boletim de Medição'!$7:$7),""),"") | E32: =IFERROR(_xlfn.XLOOKUP(A32,'2. Boletim de Medição'!$10:$10,'2. Boletim de Medição'!$13:$13),0) -> 0 | F32: =IFERROR(_xlfn.XLOOKUP(A32,'2. Boletim de Medição'!$10:$10,'2. Boletim de Medição'!$34:$34),0) -> 0 | G32: =IFERROR(E32*#REF!,0) -> 0 | H32: =IFERROR(E32-F32-G32,0) -> 0 | I32: =IF(E32>0,I31-E32,0) -> 0 | J32: =IFERROR(_xlfn.XLOOKUP(A32,'3. Faturamento Direto'!$9:$9,'3. Faturamento Direto'!$13:$13),0) -> 0 | K32: =IF(J32>0,K31-J32,0) -> 0 | L32: =E32+J32 -> 0 | M32: =IF(L32>0,M31-L32,0) -> 0 | N32: =IF(M32>0,M32/#REF!,"")
A33: =A32+1 -> 32 | B33: =IF(IFERROR(_xlfn.XLOOKUP(A33,'2. Boletim de Medição'!$10:$10,'2. Boletim de Medição'!$6:$6),"")>0,IFERROR(_xlfn.XLOOKUP(A33,'2. Boletim de Medição'!$10:$10,'2. Boletim de Medição'!$6:$6),""),"") | C33: =IF(IFERROR(_xlfn.XLOOKUP(A33,'2. Boletim de Medição'!$10:$10,'2. Boletim de Medição'!$7:$7),"")>0,IFERROR(_xlfn.XLOOKUP(A33,'2. Boletim de Medição'!$10:$10,'2. Boletim de Medição'!$7:$7),""),"") | E33: =IFERROR(_xlfn.XLOOKUP(A33,'2. Boletim de Medição'!$10:$10,'2. Boletim de Medição'!$13:$13),0) -> 0 | F33: =IFERROR(_xlfn.XLOOKUP(A33,'2. Boletim de Medição'!$10:$10,'2. Boletim de Medição'!$34:$34),0) -> 0 | G33: =IFERROR(E33*#REF!,0) -> 0 | H33: =IFERROR(E33-F33-G33,0) -> 0 | I33: =IF(E33>0,I32-E33,0) -> 0 | J33: =IFERROR(_xlfn.XLOOKUP(A33,'3. Faturamento Direto'!$9:$9,'3. Faturamento Direto'!$13:$13),0) -> 0 | K33: =IF(J33>0,K32-J33,0) -> 0 | L33: =E33+J33 -> 0 | M33: =IF(L33>0,M32-L33,0) -> 0 | N33: =IF(M33>0,M33/#REF!,"")
... A37: =A36+1 -> 36 | B37: =IF(IFERROR(_xlfn.XLOOKUP(A37,'2. Boletim de Medição'!$10:$10,'2. Boletim de Medição'!$6:$6),"")>0,IFERROR(_xlfn.XLOOKUP(A37,'2. Boletim de Medição'!$10:$10,'2. Boletim de Medição'!$6:$6),""),"") | C37: =IF(IFERROR(_xlfn.XLOOKUP(A37,'2. Boletim de Medição'!$10:$10,'2. Boletim de Medição'!$7:$7),"")>0,IFERROR(_xlfn.XLOOKUP(A37,'2. Boletim de Medição'!$10:$10,'2. Boletim de Medição'!$7:$7),""),"") | E37: =IFERROR(_xlfn.XLOOKUP(A37,'2. Boletim de Medição'!$10:$10,'2. Boletim de Medição'!$13:$13),0) -> 0 | F37: =IFERROR(_xlfn.XLOOKUP(A37,'2. Boletim de Medição'!$10:$10,'2. Boletim de Medição'!$34:$34),0) -> 0 | G37: =IFERROR(E37*#REF!,0) -> 0 | H37: =IFERROR(E37-F37-G37,0) -> 0 | I37: =IF(E37>0,I36-E37,0) -> 0 | J37: =IFERROR(_xlfn.XLOOKUP(A37,'3. Faturamento Direto'!$9:$9,'3. Faturamento Direto'!$13:$13),0) -> 0 | K37: =IF(J37>0,K36-J37,0) -> 0 | L37: =E37+J37 -> 0 | M37: =IF(L37>0,M36-L37,0) -> 0 | N37: =IF(M37>0,M37/#REF!,"")

Sheet tbFisico
A1: MEDIÇÃO | B1: EXECUTADO
A2: 1 | B2: =IF(SUM(tbBoletim!M2:M15)=0,"",SUM(tbBoletim!M2:M15)) -> 2136
A3: 2 | B3: =SUM(tbBoletim!O2:O15) -> 1405
A4: 3 | B4: =IF(SUM(tbBoletim!Q2:Q15)=0,"",SUM(tbBoletim!Q2:Q15)) -> 796
A5: 4 | B5: =IF(SUM(tbBoletim!S2:S15)=0,"",SUM(tbBoletim!S2:S15)) -> 829.79
A6: 5 | B6: =IF(SUM(tbBoletim!U2:U15)=0,"",SUM(tbBoletim!U2:U15)) -> 56
A7: 6 | B7: =IF(SUM(tbBoletim!W2:W15)=0,"",SUM(tbBoletim!W2:W15))
A8: 7 | B8: =IF(SUM(tbBoletim!Y2:Y15)=0,"",SUM(tbBoletim!Y2:Y15))
A9: 8 | B9: =IF(SUM(tbBoletim!AA2:AA15)=0,"",SUM(tbBoletim!AA2:AA15))
A10: 9 | B10: =IF(SUM(tbBoletim!AC2:AC15)=0,"",SUM(tbBoletim!AC2:AC15))
A11: 10 | B11: =IF(SUM(tbBoletim!AE2:AE15)=0,"",SUM(tbBoletim!AE2:AE15))

Sheet tbBoletim
A1: ITEM | B1: CÓDIGO TAREFA | C1: DESCRIÇÃO DO ITEM | D1: UNIDADE | E1: QUANTIDADE | F1: UNITÁRIO | G1: PESO | H1: TOTAL | I1: TOTAL MEDIDO | J1: VALOR MEDIDO | K1: SALDO | L1: VALOR SALDO | M1: MEDIÇÃO 1 | N1: VALOR MEDIÇÃO 1 | O1: MEDIÇÃO 2 | P1: VALOR MEDIÇÃO 2 | Q1: MEDIÇÃO 3 | R1: VALOR MEDIÇÃO 3 | S1: MEDIÇÃO 4 | T1: VALOR MEDIÇÃO 4 | U1: MEDIÇÃO 5 | V1: VALOR MEDIÇÃO 5 | W1: MEDIÇÃO 6 | X1: VALOR MEDIÇÃO 6 | Y1: MEDIÇÃO 7 | Z1: VALOR MEDIÇÃO 7 | AA1: MEDIÇÃO 8 | AB1: VALOR MEDIÇÃO 8 | AC1: MEDIÇÃO 9 | AD1: VALOR MEDIÇÃO 9 | AE1: MEDIÇÃO 10 | AF1: VALOR MEDIÇÃO 10
A2: 1.1 | B2: ='2. Boletim de Medição'!C17 -> 0 | C2: ='2. Boletim de Medição'!D17 -> INSTALAÇÕES ELÉTRICAS | D2: ='2. Boletim de Medição'!E17 -> 0 | E2: ='2. Boletim de Medição'!F17 -> 0 | F2: ='2. Boletim de Medição'!G17 -> 0 | G2: ='2. Boletim de Medição'!H17 -> 1 | H2: ='2. Boletim de Medição'!I17 -> 213840 | I2: ='2. Boletim de Medição'!L17 -> 0 | J2: ='2. Boletim de Medição'!M17 -> 101067.8 | K2: ='2. Boletim de Medição'!P17 -> 0 | L2: ='2. Boletim de Medição'!Q17 -> 112772.2 | M2: ='2. Boletim de Medição'!S17 -> 0 | N2: ='2. Boletim de Medição'!T17 -> 42170 | O2: ='2. Boletim de Medição'!V17 -> 0 | P2: ='2. Boletim de Medição'!W17 -> 27310 | Q2: ='2. Boletim de Medição'!Z17 -> 0 | R2: ='2. Boletim de Medição'!AA17 -> 14285 | S2: ='2. Boletim de Medição'!AC17 -> 0 | T2: ='2. Boletim de Medição'!AD17 -> 15902.8 | U2: ='2. Boletim de Medição'!AF17 -> 0 | V2: ='2. Boletim de Medição'!AG17 -> 1400 | W2: ='2. Boletim de Medição'!AI17 -> 0 | X2: ='2. Boletim de Medição'!AJ17 -> 0 | Y2: ='2. Boletim de Medição'!AL17 -> 0 | Z2: ='2. Boletim de Medição'!AM17 -> 0 | AA2: ='2. Boletim de Medição'!AO17 -> 0 | AB2: ='2. Boletim de Medição'!AP17 -> 0 | AC2: ='2. Boletim de Medição'!AR17 -> 0 | AD2: ='2. Boletim de Medição'!AS17 -> 0 | AE2: ='2. Boletim de Medição'!AU17 -> 0 | AF2: ='2. Boletim de Medição'!AV17 -> 0
A3: 1.1.1 | B3: ='2. Boletim de Medição'!C18 -> 0 | C3: ='2. Boletim de Medição'!D18 -> Mao de Obra Colocacao de Azulejo | D3: ='2. Boletim de Medição'!E18 -> M² | E3: ='2. Boletim de Medição'!F18 -> 1081 | F3: ='2. Boletim de Medição'!G18 -> 20 | G3: ='2. Boletim de Medição'!H18 -> 0.10110363 | H3: ='2. Boletim de Medição'!I18 -> 21620 | I3: ='2. Boletim de Medição'!L18 -> 262.79 | J3: ='2. Boletim de Medição'!M18 -> 5255.8 | K3: ='2. Boletim de Medição'!P18 -> 818.21 | L3: ='2. Boletim de Medição'!Q18 -> 16364.2 | M3: ='2. Boletim de Medição'!S18 -> 0 | N3: ='2. Boletim de Medição'!T18 -> 0 | O3: ='2. Boletim de Medição'!V18 -> 0 | P3: ='2. Boletim de Medição'!W18 -> 0 | Q3: ='2. Boletim de Medição'!Z18 -> 0 | R3: ='2. Boletim de Medição'!AA18 -> 0 | S3: ='2. Boletim de Medição'!AC18 -> 262.79 | T3: ='2. Boletim de Medição'!AD18 -> 5255.8 | U3: ='2. Boletim de Medição'!AF18 -> 0 | V3: ='2. Boletim de Medição'!AG18 -> 0 | W3: ='2. Boletim de Medição'!AI18 -> 0 | X3: ='2. Boletim de Medição'!AJ18 -> 0 | Y3: ='2. Boletim de Medição'!AL18 -> 0 | Z3: ='2. Boletim de Medição'!AM18 -> 0 | AA3: ='2. Boletim de Medição'!AO18 -> 0 | AB3: ='2. Boletim de Medição'!AP18 -> 0 | AC3: ='2. Boletim de Medição'!AR18 -> 0 | AD3: ='2. Boletim de Medição'!AS18 -> 0 | AE3: ='2. Boletim de Medição'!AU18 -> 0 | AF3: ='2. Boletim de Medição'!AV18 -> 0
A4: 1.1.2 | B4: ='2. Boletim de Medição'!C19 -> 0 | C4: ='2. Boletim de Medição'!D19 -> Mao de Obra Colocacao Piso Ceramico | D4: ='2. Boletim de Medição'!E19 -> M² | E4: ='2. Boletim de Medição'!F19 -> 3028 | F4: ='2. Boletim de Medição'!G19 -> 25 | G4: ='2. Boletim de Medição'!H19 -> 0.35400299 | H4: ='2. Boletim de Medição'!I19 -> 75700 | I4: ='2. Boletim de Medição'!L19 -> 2046.2 | J4: ='2. Boletim de Medição'!M19 -> 51155 | K4: ='2. Boletim de Medição'!P19 -> 981.8 | L4: ='2. Boletim de Medição'!Q19 -> 24545 | M4: ='2. Boletim de Medição'!S19 -> 1013 | N4: ='2. Boletim de Medição'!T19 -> 25325 | O4: ='2. Boletim de Medição'!V19 -> 581 | P4: ='2. Boletim de Medição'!W19 -> 14525 | Q4: ='2. Boletim de Medição'!Z19 -> 238 | R4: ='2. Boletim de Medição'!AA19 -> 5950 | S4: ='2. Boletim de Medição'!AC19 -> 214.2 | T4: ='2. Boletim de Medição'!AD19 -> 5355 | U4: ='2. Boletim de Medição'!AF19 -> 0 | V4: ='2. Boletim de Medição'!AG19 -> 0 | W4: ='2. Boletim de Medição'!AI19 -> 0 | X4: ='2. Boletim de Medição'!AJ19 -> 0 | Y4: ='2. Boletim de Medição'!AL19 -> 0 | Z4: ='2. Boletim de Medição'!AM19 -> 0 | AA4: ='2. Boletim de Medição'!AO19 -> 0 | AB4: ='2. Boletim de Medição'!AP19 -> 0 | AC4: ='2. Boletim de Medição'!AR19 -> 0 | AD4: ='2. Boletim de Medição'!AS19 -> 0 | AE4: ='2. Boletim de Medição'!AU19 -> 0 | AF4: ='2. Boletim de Medição'!AV19 -> 0
A5: 1.1.3 | B5: ='2. Boletim de Medição'!C20 -> 0 | C5: ='2. Boletim de Medição'!D20 -> M.O para colocação de soleiras | D5: ='2. Boletim de Medição'!E20 -> M | E5: ='2. Boletim de Medição'!F20 -> 337 | F5: ='2. Boletim de Medição'!G20 -> 10 | G5: ='2. Boletim de Medição'!H20 -> 0.015759446 | H5: ='2. Boletim de Medição'!I20 -> 3370 | I5: ='2. Boletim de Medição'!L20 -> 204 | J5: ='2. Boletim de Medição'!M20 -> 2040 | K5: ='2. Boletim de Medição'!P20 -> 133 | L5: ='2. Boletim de Medição'!Q20 -> 1330 | M5: ='2. Boletim de Medição'!S20 -> 0 | N5: ='2. Boletim de Medição'!T20 -> 0 | O5: ='2. Boletim de Medição'!V20 -> 155 | P5: ='2. Boletim de Medição'!W20 -> 1550 | Q5: ='2. Boletim de Medição'!Z20 -> 49 | R5: ='2. Boletim de Medição'!AA20 -> 490 | S5: ='2. Boletim de Medição'!AC20 -> 0 | T5: ='2. Boletim de Medição'!AD20 -> 0 | U5: ='2. Boletim de Medição'!AF20 -> 0 | V5: ='2. Boletim de Medição'!AG20 -> 0 | W5: ='2. Boletim de Medição'!AI20 -> 0 | X5: ='2. Boletim de Medição'!AJ20 -> 0 | Y5: ='2. Boletim de Medição'!AL20 -> 0 | Z5: ='2. Boletim de Medição'!AM20 -> 0 | AA5: ='2. Boletim de Medição'!AO20 -> 0 | AB5: ='2. Boletim de Medição'!AP20 -> 0 | AC5: ='2. Boletim de Medição'!AR20 -> 0 | AD5: ='2. Boletim de Medição'!AS20 -> 0 | AE5: ='2. Boletim de Medição'!AU20 -> 0 | AF5: ='2. Boletim de Medição'!AV20 -> 0
A6: 1.1.4 | B6: ='2. Boletim de Medição'!C21 -> 0 | C6: ='2. Boletim de Medição'!D21 -> M.O. para colocação de baguetes | D6: ='2. Boletim de Medição'!E21 -> M | E6: ='2. Boletim de Medição'!F21 -> 353 | F6: ='2. Boletim de Medição'!G21 -> 25 | G6: ='2. Boletim de Medição'!H21 -> 0.041269173 | H6: ='2. Boletim de Medição'!I21 -> 8825 | I6: ='2. Boletim de Medição'!L21 -> 197 | J6: ='2. Boletim de Medição'!M21 -> 4925 | K6: ='2. Boletim de Medição'!P21 -> 156 | L6: ='2. Boletim de Medição'!Q21 -> 3900 | M6: ='2. Boletim de Medição'!S21 -> 0 | N6: ='2. Boletim de Medição'!T21 -> 0 | O6: ='2. Boletim de Medição'!V21 -> 120 | P6: ='2. Boletim de Medição'!W21 -> 3000 | Q6: ='2. Boletim de Medição'!Z21 -> 21 | R6: ='2. Boletim de Medição'!AA21 -> 525 | S6: ='2. Boletim de Medição'!AC21 -> 0 | T6: ='2. Boletim de Medição'!AD21 -> 0 | U6: ='2. Boletim de Medição'!AF21 -> 56 | V6: ='2. Boletim de Medição'!AG21 -> 1400 | W6: ='2. Boletim de Medição'!AI21 -> 0 | X6: ='2. Boletim de Medição'!AJ21 -> 0 | Y6: ='2. Boletim de Medição'!AL21 -> 0 | Z6: ='2. Boletim de Medição'!AM21 -> 0 | AA6: ='2. Boletim de Medição'!AO21 -> 0 | AB6: ='2. Boletim de Medição'!AP21 -> 0 | AC6: ='2. Boletim de Medição'!AR21 -> 0 | AD6: ='2. Boletim de Medição'!AS21 -> 0 | AE6: ='2. Boletim de Medição'!AU21 -> 0 | AF6: ='2. Boletim de Medição'!AV21 -> 0
A7: 1.1.5 | B7: ='2. Boletim de Medição'!C22 -> 0 | C7: ='2. Boletim de Medição'!D22 -> Rodapé Cerâmico | Porcelanato - Serviço M.O Subcontrato | D7: ='2. Boletim de Medição'!E22 -> M | E7: ='2. Boletim de Medição'!F22 -> 6955 | F7: ='2. Boletim de Medição'!G22 -> 15 | G7: ='2. Boletim de Medição'!H22 -> 0.48786476 | H7: ='2. Boletim de Medição'!I22 -> 104325 | I7: ='2. Boletim de Medição'!L22 -> 2512.8 | J7: ='2. Boletim de Medição'!M22 -> 37692 | K7: ='2. Boletim de Medição'!P22 -> 4442.2 | L7: ='2. Boletim de Medição'!Q22 -> 66633 | M7: ='2. Boletim de Medição'!S22 -> 1123 | N7: ='2. Boletim de Medição'!T22 -> 16845 | O7: ='2. Boletim de Medição'!V22 -> 549 | P7: ='2. Boletim de Medição'!W22 -> 8235 | Q7: ='2. Boletim de Medição'!Z22 -> 488 | R7: ='2. Boletim de Medição'!AA22 -> 7320 | S7: ='2. Boletim de Medição'!AC22 -> 352.8 | T7: ='2. Boletim de Medição'!AD22 -> 5292 | U7: ='2. Boletim de Medição'!AF22 -> 0 | V7: ='2. Boletim de Medição'!AG22 -> 0 | W7: ='2. Boletim de Medição'!AI22 -> 0 | X7: ='2. Boletim de Medição'!AJ22 -> 0 | Y7: ='2. Boletim de Medição'!AL22 -> 0 | Z7: ='2. Boletim de Medição'!AM22 -> 0 | AA7: ='2. Boletim de Medição'!AO22 -> 0 | AB7: ='2. Boletim de Medição'!AP22 -> 0 | AC7: ='2. Boletim de Medição'!AR22 -> 0 | AD7: ='2. Boletim de Medição'!AS22 -> 0 | AE7: ='2. Boletim de Medição'!AU22 -> 0 | AF7: ='2. Boletim de Medição'!AV22 -> 0
A8: 1.1.5 | B8: ='2. Boletim de Medição'!C23 -> 0 | C8: ='2. Boletim de Medição'!D23 -> 0 | D8: ='2. Boletim de Medição'!E23 -> 0 | E8: ='2. Boletim de Medição'!F23 -> 0 | F8: ='2. Boletim de Medição'!G23 -> 0 | G8: ='2. Boletim de Medição'!H23 -> 0 | H8: ='2. Boletim de Medição'!I23 -> 0 | I8: ='2. Boletim de Medição'!L23 -> 0 | J8: ='2. Boletim de Medição'!M23 -> 0 | K8: ='2. Boletim de Medição'!P23 -> 0 | L8: ='2. Boletim de Medição'!Q23 -> 0 | M8: ='2. Boletim de Medição'!S23 -> 0 | N8: ='2. Boletim de Medição'!T23 -> 0 | O8: ='2. Boletim de Medição'!V23 -> 0 | P8: ='2. Boletim de Medição'!W23 -> 0 | Q8: ='2. Boletim de Medição'!Z23 -> 0 | R8: ='2. Boletim de Medição'!AA23 -> 0 | S8: ='2. Boletim de Medição'!AC23 -> 0 | T8: ='2. Boletim de Medição'!AD23 -> 0 | U8: ='2. Boletim de Medição'!AF23 -> 0 | V8: ='2. Boletim de Medição'!AG23 -> 0 | W8: ='2. Boletim de Medição'!AI23 -> 0 | X8: ='2. Boletim de Medição'!AJ23 -> 0 | Y8: ='2. Boletim de Medição'!AL23 -> 0 | Z8: ='2. Boletim de Medição'!AM23 -> 0 | AA8: ='2. Boletim de Medição'!AO23 -> 0 | AB8: ='2. Boletim de Medição'!AP23 -> 0 | AC8: ='2. Boletim de Medição'!AR23 -> 0 | AD8: ='2. Boletim de Medição'!AS23 -> 0 | AE8: ='2. Boletim de Medição'!AU23 -> 0 | AF8: ='2. Boletim de Medição'!AV23 -> 0
A9: 1.1.6 | B9: ='2. Boletim de Medição'!C24 -> 0 | C9: ='2. Boletim de Medição'!D24 -> 0 | D9: ='2. Boletim de Medição'!E24 -> 0 | E9: ='2. Boletim de Medição'!F24 -> 0 | F9: ='2. Boletim de Medição'!G24 -> 0 | G9: ='2. Boletim de Medição'!H24 -> 0 | H9: ='2. Boletim de Medição'!I24 -> 0 | I9: ='2. Boletim de Medição'!L24 -> 0 | J9: ='2. Boletim de Medição'!M24 -> 0 | K9: ='2. Boletim de Medição'!P24 -> 0 | L9: ='2. Boletim de Medição'!Q24 -> 0 | M9: ='2. Boletim de Medição'!S24 -> 0 | N9: ='2. Boletim de Medição'!T24 -> 0 | O9: ='2. Boletim de Medição'!V24 -> 0 | P9: ='2. Boletim de Medição'!W24 -> 0 | Q9: ='2. Boletim de Medição'!Z24 -> 0 | R9: ='2. Boletim de Medição'!AA24 -> 0 | S9: ='2. Boletim de Medição'!AC24 -> 0 | T9: ='2. Boletim de Medição'!AD24 -> 0 | U9: ='2. Boletim de Medição'!AF24 -> 0 | V9: ='2. Boletim de Medição'!AG24 -> 0 | W9: ='2. Boletim de Medição'!AI24 -> 0 | X9: ='2. Boletim de Medição'!AJ24 -> 0 | Y9: ='2. Boletim de Medição'!AL24 -> 0 | Z9: ='2. Boletim de Medição'!AM24 -> 0 | AA9: ='2. Boletim de Medição'!AO24 -> 0 | AB9: ='2. Boletim de Medição'!AP24 -> 0 | AC9: ='2. Boletim de Medição'!AR24 -> 0 | AD9: ='2. Boletim de Medição'!AS24 -> 0 | AE9: ='2. Boletim de Medição'!AU24 -> 0 | AF9: ='2. Boletim de Medição'!AV24 -> 0
A10: 1.1.7 | B10: ='2. Boletim de Medição'!C25 -> 0 | C10: ='2. Boletim de Medição'!D25 -> 0 | D10: ='2. Boletim de Medição'!E25 -> 0 | E10: ='2. Boletim de Medição'!F25 -> 0 | F10: ='2. Boletim de Medição'!G25 -> 0 | G10: ='2. Boletim de Medição'!H25 -> 0 | H10: ='2. Boletim de Medição'!I25 -> 0 | I10: ='2. Boletim de Medição'!L25 -> 0 | J10: ='2. Boletim de Medição'!M25 -> 0 | K10: ='2. Boletim de Medição'!P25 -> 0 | L10: ='2. Boletim de Medição'!Q25 -> 0 | M10: ='2. Boletim de Medição'!S25 -> 0 | N10: ='2. Boletim de Medição'!T25 -> 0 | O10: ='2. Boletim de Medição'!V25 -> 0 | P10: ='2. Boletim de Medição'!W25 -> 0 | Q10: ='2. Boletim de Medição'!Z25 -> 0 | R10: ='2. Boletim de Medição'!AA25 -> 0 | S10: ='2. Boletim de Medição'!AC25 -> 0 | T10: ='2. Boletim de Medição'!AD25 -> 0 | U10: ='2. Boletim de Medição'!AF25 -> 0 | V10: ='2. Boletim de Medição'!AG25 -> 0 | W10: ='2. Boletim de Medição'!AI25 -> 0 | X10: ='2. Boletim de Medição'!AJ25 -> 0 | Y10: ='2. Boletim de Medição'!AL25 -> 0 | Z10: ='2. Boletim de Medição'!AM25 -> 0 | AA10: ='2. Boletim de Medição'!AO25 -> 0 | AB10: ='2. Boletim de Medição'!AP25 -> 0 | AC10: ='2. Boletim de Medição'!AR25 -> 0 | AD10: ='2. Boletim de Medição'!AS25 -> 0 | AE10: ='2. Boletim de Medição'!AU25 -> 0 | AF10: ='2. Boletim de Medição'!AV25 -> 0
A11: 1.7 | B11: ='2. Boletim de Medição'!C26 -> 0 | C11: ='2. Boletim de Medição'!D26 -> 0 | D11: ='2. Boletim de Medição'!E26 -> 0 | E11: ='2. Boletim de Medição'!F26 -> 0 | F11: ='2. Boletim de Medição'!G26 -> 0 | G11: ='2. Boletim de Medição'!H26 -> 0 | H11: ='2. Boletim de Medição'!I26 -> 0 | I11: ='2. Boletim de Medição'!L26 -> 0 | J11: ='2. Boletim de Medição'!M26 -> 0 | K11: ='2. Boletim de Medição'!P26 -> 0 | L11: ='2. Boletim de Medição'!Q26 -> 0 | M11: ='2. Boletim de Medição'!S26 -> 0 | N11: ='2. Boletim de Medição'!T26 -> 0 | O11: ='2. Boletim de Medição'!V26 -> 0 | P11: ='2. Boletim de Medição'!W26 -> 0 | Q11: ='2. Boletim de Medição'!Z26 -> 0 | R11: ='2. Boletim de Medição'!AA26 -> 0 | S11: ='2. Boletim de Medição'!AC26 -> 0 | T11: ='2. Boletim de Medição'!AD26 -> 0 | U11: ='2. Boletim de Medição'!AF26 -> 0 | V11: ='2. Boletim de Medição'!AG26 -> 0 | W11: ='2. Boletim de Medição'!AI26 -> 0 | X11: ='2. Boletim de Medição'!AJ26 -> 0 | Y11: ='2. Boletim de Medição'!AL26 -> 0 | Z11: ='2. Boletim de Medição'!AM26 -> 0 | AA11: ='2. Boletim de Medição'!AO26 -> 0 | AB11: ='2. Boletim de Medição'!AP26 -> 0 | AC11: ='2. Boletim de Medição'!AR26 -> 0 | AD11: ='2. Boletim de Medição'!AS26 -> #REF! | AE11: ='2. Boletim de Medição'!AU26 -> 0 | AF11: ='2. Boletim de Medição'!AV26 -> 0
A12: 1.7.1 | B12: ='2. Boletim de Medição'!C27 -> 0 | C12: ='2. Boletim de Medição'!D27 -> 0 | D12: ='2. Boletim de Medição'!E27 -> 0 | E12: ='2. Boletim de Medição'!F27 -> 0 | F12: ='2. Boletim de Medição'!G27 -> 0 | G12: ='2. Boletim de Medição'!H27 -> 0 | H12: ='2. Boletim de Medição'!I27 -> 0 | I12: ='2. Boletim de Medição'!L27 -> 0 | J12: ='2. Boletim de Medição'!M27 -> 0 | K12: ='2. Boletim de Medição'!P27 -> 0 | L12: ='2. Boletim de Medição'!Q27 -> 0 | M12: ='2. Boletim de Medição'!S27 -> 0 | N12: ='2. Boletim de Medição'!T27 -> 0 | O12: ='2. Boletim de Medição'!V27 -> 0 | P12: ='2. Boletim de Medição'!W27 -> 0 | Q12: ='2. Boletim de Medição'!Z27 -> 0 | R12: ='2. Boletim de Medição'!AA27 -> 0 | S12: ='2. Boletim de Medição'!AC27 -> 0 | T12: ='2. Boletim de Medição'!AD27 -> 0 | U12: ='2. Boletim de Medição'!AF27 -> 0 | V12: ='2. Boletim de Medição'!AG27 -> 0 | W12: ='2. Boletim de Medição'!AI27 -> 0 | X12: ='2. Boletim de Medição'!AJ27 -> 0 | Y12: ='2. Boletim de Medição'!AL27 -> 0 | Z12: ='2. Boletim de Medição'!AM27 -> 0 | AA12: ='2. Boletim de Medição'!AO27 -> 0 | AB12: ='2. Boletim de Medição'!AP27 -> 0 | AC12: ='2. Boletim de Medição'!AR27 -> 0 | AD12: ='2. Boletim de Medição'!AS27 -> 0 | AE12: ='2. Boletim de Medição'!AU27 -> 0 | AF12: ='2. Boletim de Medição'!AV27 -> 0
A13: 1.5.2 | B13: ='2. Boletim de Medição'!C28 -> 0 | C13: ='2. Boletim de Medição'!D28 -> 0 | D13: ='2. Boletim de Medição'!E28 -> 0 | E13: ='2. Boletim de Medição'!F28 -> 0 | F13: ='2. Boletim de Medição'!G28 -> 0 | G13: ='2. Boletim de Medição'!H28 -> 0 | H13: ='2. Boletim de Medição'!I28 -> 0 | I13: ='2. Boletim de Medição'!L28 -> 0 | J13: ='2. Boletim de Medição'!M28 -> 0 | K13: ='2. Boletim de Medição'!P28 -> 0 | L13: ='2. Boletim de Medição'!Q28 -> 0 | M13: ='2. Boletim de Medição'!S28 -> 0 | N13: ='2. Boletim de Medição'!T28 -> 0 | O13: ='2. Boletim de Medição'!V28 -> 0 | P13: ='2. Boletim de Medição'!W28 -> 0 | Q13: ='2. Boletim de Medição'!Z28 -> 0 | R13: ='2. Boletim de Medição'!AA28 -> 0 | S13: ='2. Boletim de Medição'!AC28 -> 0 | T13: ='2. Boletim de Medição'!AD28 -> 0 | U13: ='2. Boletim de Medição'!AF28 -> 0 | V13: ='2. Boletim de Medição'!AG28 -> 0 | W13: ='2. Boletim de Medição'!AI28 -> 0 | X13: ='2. Boletim de Medição'!AJ28 -> 0 | Y13: ='2. Boletim de Medição'!AL28 -> 0 | Z13: ='2. Boletim de Medição'!AM28 -> 0 | AA13: ='2. Boletim de Medição'!AO28 -> 0 | AB13: ='2. Boletim de Medição'!AP28 -> 0 | AC13: ='2. Boletim de Medição'!AR28 -> 0 | AD13: ='2. Boletim de Medição'!AS28 -> 0 | AE13: ='2. Boletim de Medição'!AU28 -> 0 | AF13: ='2. Boletim de Medição'!AV28 -> 0
... A15: 1.5.4 | B15: ='2. Boletim de Medição'!C30 -> 0 | C15: ='2. Boletim de Medição'!D30 -> 0 | D15: ='2. Boletim de Medição'!E30 -> 0 | E15: ='2. Boletim de Medição'!F30 -> 0 | F15: ='2. Boletim de Medição'!G30 -> 0 | G15: ='2. Boletim de Medição'!H30 -> 0 | H15: ='2. Boletim de Medição'!I30 -> 0 | I15: ='2. Boletim de Medição'!L30 -> 0 | J15: ='2. Boletim de Medição'!M30 -> 0 | K15: ='2. Boletim de Medição'!P30 -> 0 | L15: ='2. Boletim de Medição'!Q30 -> 0 | M15: ='2. Boletim de Medição'!S30 -> 0 | N15: ='2. Boletim de Medição'!T30 -> 0 | O15: ='2. Boletim de Medição'!V30 -> 0 | P15: ='2. Boletim de Medição'!W30 -> 0 | Q15: ='2. Boletim de Medição'!Z30 -> 0 | R15: ='2. Boletim de Medição'!AA30 -> 0 | S15: ='2. Boletim de Medição'!AC30 -> 0 | T15: ='2. Boletim de Medição'!AD30 -> 0 | U15: ='2. Boletim de Medição'!AF30 -> 0 | V15: ='2. Boletim de Medição'!AG30 -> 0 | W15: ='2. Boletim de Medição'!AI30 -> 0 | X15: ='2. Boletim de Medição'!AJ30 -> 0 | Y15: ='2. Boletim de Medição'!AL30 -> 0 | Z15: ='2. Boletim de Medição'!AM30 -> 0 | AA15: ='2. Boletim de Medição'!AO30 -> 0 | AB15: ='2. Boletim de Medição'!AP30 -> 0 | AC15: ='2. Boletim de Medição'!AR30 -> 0 | AD15: ='2. Boletim de Medição'!AS30 -> 0 | AE15: ='2. Boletim de Medição'!AU30 -> 0 | AF15: ='2. Boletim de Medição'!AV30 -> 0
A16: D.1 | B16: ='2. Boletim de Medição'!C34 -> 0 | C16: ='2. Boletim de Medição'!I34 -> DEDUÇÃO | D16: ='2. Boletim de Medição'!E34 -> 0 | E16: ='2. Boletim de Medição'!F34 -> 0 | F16: ='2. Boletim de Medição'!G34 -> 0 | G16: ='2. Boletim de Medição'!H34 -> 0 | H16: ='2. Boletim de Medição'!M34 -> 0 | I16: ='2. Boletim de Medição'!L34 -> 0 | J16: ='2. Boletim de Medição'!M34 -> 0 | K16: ='2. Boletim de Medição'!O34 -> 0 | L16: ='2. Boletim de Medição'!Q34 -> 0 | M16: ='2. Boletim de Medição'!S34 -> 0 | N16: ='2. Boletim de Medição'!T32 -> 2951.9 | O16: ='2. Boletim de Medição'!V34 -> 0 | P16: ='2. Boletim de Medição'!W32 -> 1911.7 | Q16: ='2. Boletim de Medição'!Z34 -> 0 | R16: ='2. Boletim de Medição'!AA32 -> 999.95 | S16: ='2. Boletim de Medição'!AC34 -> 0 | T16: ='2. Boletim de Medição'!AD32 -> 1113.196 | U16: ='2. Boletim de Medição'!AF34 -> 0 | V16: ='2. Boletim de Medição'!AG32 -> 98 | W16: ='2. Boletim de Medição'!AI34 -> 0 | X16: ='2. Boletim de Medição'!AJ32 -> 0 | Y16: ='2. Boletim de Medição'!AL34 -> 0 | Z16: ='2. Boletim de Medição'!AM32 -> 0 | AA16: ='2. Boletim de Medição'!AO34 -> 0 | AB16: ='2. Boletim de Medição'!AP32 -> 0 | AC16: ='2. Boletim de Medição'!AR34 -> 0 | AD16: ='2. Boletim de Medição'!AS32 -> #REF! | AE16: ='2. Boletim de Medição'!AV32 -> 0 | AF16: ='2. Boletim de Medição'!AV34 -> 0
A17: D.1.1 | B17: ='2. Boletim de Medição'!C32 -> 0 | C17: ='2. Boletim de Medição'!I35 -> ALIMENTAÇÃO | D17: ='2. Boletim de Medição'!E35 -> 0 | E17: ='2. Boletim de Medição'!F35 -> 0 | F17: ='2. Boletim de Medição'!G35 -> 0 | G17: ='2. Boletim de Medição'!H35 -> 0 | H17: ='2. Boletim de Medição'!M35 -> 0 | I17: ='2. Boletim de Medição'!L35 -> 0 | J17: ='2. Boletim de Medição'!M35 -> 0 | K17: ='2. Boletim de Medição'!O35 -> 0 | L17: ='2. Boletim de Medição'!Q35 -> 0 | M17: ='2. Boletim de Medição'!S35 -> 0 | N17: ='2. Boletim de Medição'!T35 -> 0 | O17: ='2. Boletim de Medição'!V35 -> 0 | P17: ='2. Boletim de Medição'!W35 -> 0 | Q17: ='2. Boletim de Medição'!Z35 -> 0 | R17: ='2. Boletim de Medição'!AA35 -> 0 | S17: ='2. Boletim de Medição'!AC35 -> 0 | T17: ='2. Boletim de Medição'!AD35 -> 0 | U17: ='2. Boletim de Medição'!AF35 -> 0 | V17: ='2. Boletim de Medição'!AG35 -> 0 | W17: ='2. Boletim de Medição'!AI35 -> 0 | X17: ='2. Boletim de Medição'!AJ35 -> 0 | Y17: ='2. Boletim de Medição'!AL35 -> 0 | Z17: ='2. Boletim de Medição'!AM35 -> 0 | AA17: ='2. Boletim de Medição'!AO35 -> 0 | AB17: ='2. Boletim de Medição'!AP35 -> 0 | AC17: ='2. Boletim de Medição'!AR35 -> 0 | AD17: ='2. Boletim de Medição'!AS35 -> 0 | AE17: ='2. Boletim de Medição'!AU35 -> 0 | AF17: ='2. Boletim de Medição'!AV35 -> 0
A18: D.1.2 | B18: ='2. Boletim de Medição'!C33 -> 0 | C18: ='2. Boletim de Medição'!I36 -> ALOJAMENTO | D18: ='2. Boletim de Medição'!E36 -> 0 | E18: ='2. Boletim de Medição'!F36 -> 0 | F18: ='2. Boletim de Medição'!G36 -> 0 | G18: ='2. Boletim de Medição'!H36 -> 0 | H18: ='2. Boletim de Medição'!M36 -> 0 | I18: ='2. Boletim de Medição'!L36 -> 0 | J18: ='2. Boletim de Medição'!M36 -> 0 | K18: ='2. Boletim de Medição'!O36 -> 0 | L18: ='2. Boletim de Medição'!Q36 -> 0 | M18: ='2. Boletim de Medição'!S36 -> 0 | N18: ='2. Boletim de Medição'!T36 -> 0 | O18: ='2. Boletim de Medição'!V36 -> 0 | P18: ='2. Boletim de Medição'!W36 -> 0 | Q18: ='2. Boletim de Medição'!Z36 -> 0 | R18: ='2. Boletim de Medição'!AA36 -> 0 | S18: ='2. Boletim de Medição'!AC36 -> 0 | T18: ='2. Boletim de Medição'!AD36 -> 0 | U18: ='2. Boletim de Medição'!AF36 -> 0 | V18: ='2. Boletim de Medição'!AG36 -> 0 | W18: ='2. Boletim de Medição'!AI36 -> 0 | X18: ='2. Boletim de Medição'!AJ36 -> 0 | Y18: ='2. Boletim de Medição'!AL36 -> 0 | Z18: ='2. Boletim de Medição'!AM36 -> 0 | AA18: ='2. Boletim de Medição'!AO36 -> 0 | AB18: ='2. Boletim de Medição'!AP36 -> 0 | AC18: ='2. Boletim de Medição'!AR36 -> 0 | AD18: ='2. Boletim de Medição'!AS36 -> 0 | AE18: ='2. Boletim de Medição'!AU36 -> 0 | AF18: ='2. Boletim de Medição'!AV36 -> 0
A19: D.1.3 | B19: ='2. Boletim de Medição'!C34 -> 0 | C19: ='2. Boletim de Medição'!I37 -> EPI | D19: ='2. Boletim de Medição'!E37 -> 0 | E19: ='2. Boletim de Medição'!F37 -> 0 | F19: ='2. Boletim de Medição'!G37 -> 0 | G19: ='2. Boletim de Medição'!H37 -> 0 | H19: ='2. Boletim de Medição'!M37 -> 0 | I19: ='2. Boletim de Medição'!L37 -> 0 | J19: ='2. Boletim de Medição'!M37 -> 0 | K19: ='2. Boletim de Medição'!O37 -> 0 | L19: ='2. Boletim de Medição'!Q37 -> 0 | M19: ='2. Boletim de Medição'!S37 -> 0 | N19: ='2. Boletim de Medição'!T37 -> 0 | O19: ='2. Boletim de Medição'!V37 -> 0 | P19: ='2. Boletim de Medição'!W37 -> 0 | Q19: ='2. Boletim de Medição'!Z37 -> 0 | R19: ='2. Boletim de Medição'!AA37 -> 0 | S19: ='2. Boletim de Medição'!AC37 -> 0 | T19: ='2. Boletim de Medição'!AD37 -> 0 | U19: ='2. Boletim de Medição'!AF37 -> 0 | V19: ='2. Boletim de Medição'!AG37 -> 0 | W19: ='2. Boletim de Medição'!AI37 -> 0 | X19: ='2. Boletim de Medição'!AJ37 -> 0 | Y19: ='2. Boletim de Medição'!AL37 -> 0 | Z19: ='2. Boletim de Medição'!AM37 -> 0 | AA19: ='2. Boletim de Medição'!AO37 -> 0 | AB19: ='2. Boletim de Medição'!AP37 -> 0 | AC19: ='2. Boletim de Medição'!AR37 -> 0 | AD19: ='2. Boletim de Medição'!AS37 -> 0 | AE19: ='2. Boletim de Medição'!AU37 -> 0 | AF19: ='2. Boletim de Medição'!AV37 -> 0
A20: D.1.4 | B20: ='2. Boletim de Medição'!C35 -> 0 | C20: ='2. Boletim de Medição'!I38 -> OUTROS (ESPECIFICAR) | D20: ='2. Boletim de Medição'!E38 -> 0 | E20: ='2. Boletim de Medição'!F38 -> 0 | F20: ='2. Boletim de Medição'!G38 -> 0 | G20: ='2. Boletim de Medição'!H38 -> 0 | H20: ='2. Boletim de Medição'!M38 -> 0 | I20: ='2. Boletim de Medição'!L38 -> 0 | J20: ='2. Boletim de Medição'!M38 -> 0 | K20: ='2. Boletim de Medição'!O38 -> 0 | L20: ='2. Boletim de Medição'!Q38 -> 0 | M20: ='2. Boletim de Medição'!S38 -> 0 | N20: ='2. Boletim de Medição'!T38 -> 0 | O20: ='2. Boletim de Medição'!V38 -> 0 | P20: ='2. Boletim de Medição'!W38 -> 0 | Q20: ='2. Boletim de Medição'!Z38 -> 0 | R20: ='2. Boletim de Medição'!AA38 -> 0 | S20: ='2. Boletim de Medição'!AC38 -> 0 | T20: ='2. Boletim de Medição'!AD38 -> 0 | U20: ='2. Boletim de Medição'!AF38 -> 0 | V20: ='2. Boletim de Medição'!AG38 -> 0 | W20: ='2. Boletim de Medição'!AI38 -> 0 | X20: ='2. Boletim de Medição'!AJ38 -> 0 | Y20: ='2. Boletim de Medição'!AL38 -> 0 | Z20: ='2. Boletim de Medição'!AM38 -> 0 | AA20: ='2. Boletim de Medição'!AO38 -> 0 | AB20: ='2. Boletim de Medição'!AP38 -> 0 | AC20: ='2. Boletim de Medição'!AR38 -> 0 | AD20: ='2. Boletim de Medição'!AS38 -> 0 | AE20: ='2. Boletim de Medição'!AU38 -> 0 | AF20: ='2. Boletim de Medição'!AV38 -> 0
A21: D.2.1 | B21: ='2. Boletim de Medição'!C37 -> 0 | C21: ='2. Boletim de Medição'!I40 -> RETENÇÃO | D21: ='2. Boletim de Medição'!E39 -> 0 | E21: ='2. Boletim de Medição'!F39 -> 0 | F21: ='2. Boletim de Medição'!G39 -> 0 | G21: ='2. Boletim de Medição'!H39 -> 0 | H21: ='2. Boletim de Medição'!M40 -> 0 | I21: ='2. Boletim de Medição'!L39 -> 0 | J21: ='2. Boletim de Medição'!M39 -> 0 | K21: ='2. Boletim de Medição'!O39 -> 0 | L21: ='2. Boletim de Medição'!Q39 -> 0 | M21: ='2. Boletim de Medição'!S39 -> 0 | N21: ='2. Boletim de Medição'!T39 -> 0 | O21: ='2. Boletim de Medição'!V39 -> 0 | P21: ='2. Boletim de Medição'!W39 -> 0 | Q21: ='2. Boletim de Medição'!Z39 -> 0 | R21: ='2. Boletim de Medição'!AA39 -> 0 | S21: ='2. Boletim de Medição'!AC39 -> 0 | T21: ='2. Boletim de Medição'!AD39 -> 0 | U21: ='2. Boletim de Medição'!AF39 -> 0 | V21: ='2. Boletim de Medição'!AG39 -> 0 | W21: ='2. Boletim de Medição'!AI39 -> 0 | X21: ='2. Boletim de Medição'!AJ39 -> 0 | Y21: ='2. Boletim de Medição'!AL39 -> 0 | Z21: ='2. Boletim de Medição'!AM39 -> 0 | AA21: ='2. Boletim de Medição'!AO39 -> 0 | AB21: ='2. Boletim de Medição'!AP39 -> 0 | AC21: ='2. Boletim de Medição'!AR39 -> 0 | AD21: ='2. Boletim de Medição'!AS39 -> 0 | AE21: ='2. Boletim de Medição'!AU39 -> 0 | AF21: ='2. Boletim de Medição'!AV39 -> 0

Sheet tbFaturamento
A1: ITEM | B1: CÓDIGO TAREFA | C1: DESCRIÇÃO DO ITEM | D1: PESO | E1: TOTAL | F1: TOTAL MEDIDO | G1: QUANTIDADE | H1: SALDO | I1: MEDIÇÃO 1 | K1: VALOR | M1: VALOR | O1: VALOR | Q1: VALOR | S1: VALOR | U1: VALOR | W1: VALOR | Y1: VALOR | AA1: VALOR
A2: ='3. Faturamento Direto'!B15 -> 1 | B2: ='3. Faturamento Direto'!C15 -> 0 | C2: ='3. Faturamento Direto'!D15 -> TOTAL CONTRATADO | D2: ='3. Faturamento Direto'!H15 -> #DIV/0! | E2: ='3. Faturamento Direto'!I15 -> 0 | F2: ='3. Faturamento Direto'!L15 -> 0 | G2: ='3. Faturamento Direto'!N15 -> 0 | H2: ='3. Faturamento Direto'!O15 -> 0 | I2: ='3. Faturamento Direto'!Q15 -> 0
A3: ='3. Faturamento Direto'!B17 -> 1.1 | B3: ='3. Faturamento Direto'!C17 -> 0 | C3: ='3. Faturamento Direto'!D17 -> 0 | D3: ='3. Faturamento Direto'!H17 -> #DIV/0! | E3: ='3. Faturamento Direto'!I17 -> 0 | F3: ='3. Faturamento Direto'!L17 -> 0 | G3: ='3. Faturamento Direto'!N17 -> 0 | H3: ='3. Faturamento Direto'!O17 -> 0 | I3: ='3. Faturamento Direto'!Q17 -> 0 | K3: =SUMIF($A:$A,$A3&"."&"*",K:K) -> 0 | M3: =SUMIF($A:$A,$A3&"."&"*",M:M) -> 0 | O3: =SUMIF($A:$A,$A3&"."&"*",O:O) -> 0 | Q3: =SUMIF($A:$A,$A3&"."&"*",Q:Q) -> 0 | S3: =SUMIF($A:$A,$A3&"."&"*",S:S) -> 0 | U3: =SUMIF($A:$A,$A3&"."&"*",U:U) -> 0 | W3: =SUMIF($A:$A,$A3&"."&"*",W:W) -> 0 | Y3: =SUMIF($A:$A,$A3&"."&"*",Y:Y) -> 0 | AA3: =SUMIF($A:$A,$A3&"."&"*",AA:AA) -> 0
A4: ='3. Faturamento Direto'!B18 -> 1.1.1 | B4: ='3. Faturamento Direto'!C18 -> 0 | C4: ='3. Faturamento Direto'!D18 -> 0 | D4: ='3. Faturamento Direto'!H18 -> #DIV/0! | E4: ='3. Faturamento Direto'!I18 -> 0 | F4: ='3. Faturamento Direto'!L18 -> 0 | G4: ='3. Faturamento Direto'!N18 -> #DIV/0! | H4: ='3. Faturamento Direto'!O18 -> 0 | I4: ='3. Faturamento Direto'!Q18 -> 0
A5: ='3. Faturamento Direto'!B19 -> 1.1.2 | B5: ='3. Faturamento Direto'!C19 -> 0 | C5: ='3. Faturamento Direto'!D19 -> 0 | D5: ='3. Faturamento Direto'!H19 -> #DIV/0! | E5: ='3. Faturamento Direto'!I19 -> 0 | F5: ='3. Faturamento Direto'!L19 -> 0 | G5: ='3. Faturamento Direto'!N19 -> #DIV/0! | H5: ='3. Faturamento Direto'!O19 -> 0 | I5: ='3. Faturamento Direto'!Q19 -> 0
A6: ='3. Faturamento Direto'!B20 -> 1.2 | B6: ='3. Faturamento Direto'!C20 -> 0 | C6: ='3. Faturamento Direto'!D20 -> 0 | D6: ='3. Faturamento Direto'!H20 -> #DIV/0! | E6: ='3. Faturamento Direto'!I20 -> 0 | F6: ='3. Faturamento Direto'!L20 -> 0 | G6: ='3. Faturamento Direto'!N20 -> 0 | H6: ='3. Faturamento Direto'!O20 -> 0 | I6: ='3. Faturamento Direto'!Q20 -> 0 | K6: =SUMIF($A:$A,$A6&"."&"*",K:K) -> 0 | M6: =SUMIF($A:$A,$A6&"."&"*",M:M) -> 0 | O6: =SUMIF($A:$A,$A6&"."&"*",O:O) -> 0 | Q6: =SUMIF($A:$A,$A6&"."&"*",Q:Q) -> 0 | S6: =SUMIF($A:$A,$A6&"."&"*",S:S) -> 0 | U6: =SUMIF($A:$A,$A6&"."&"*",U:U) -> 0 | W6: =SUMIF($A:$A,$A6&"."&"*",W:W) -> 0 | Y6: =SUMIF($A:$A,$A6&"."&"*",Y:Y) -> 0 | AA6: =SUMIF($A:$A,$A6&"."&"*",AA:AA) -> 0
A7: ='3. Faturamento Direto'!B21 -> 1.2.1 | B7: ='3. Faturamento Direto'!C21 -> 0 | C7: ='3. Faturamento Direto'!D21 -> 0 | D7: ='3. Faturamento Direto'!H21 -> #DIV/0! | E7: ='3. Faturamento Direto'!I21 -> 0 | F7: ='3. Faturamento Direto'!L21 -> 0 | G7: ='3. Faturamento Direto'!N21 -> #DIV/0! | H7: ='3. Faturamento Direto'!O21 -> 0 | I7: ='3. Faturamento Direto'!Q21 -> 0

Sheet DASHBOARD
AG4: ATUALIZADO EM:
AG5: =TODAY() -> 46168
E9: INDICADORES GERAIS
